<?xml version="1.0" encoding="utf-8"?>
<robot name="falcon_bravo7">

                                <material name="green2">
                                        <color rgba="0.235 0.702 0.443 1"/>
                                </material>

                                <material name="blue">
                                        <color rgba="0.263 0.733 0.984 1"/>
                                </material>

                                <material name="lavender">
                                        <color rgba="0.5 0.733 0.984 1"/>
                                </material>

                                <material name="red">
                                        <color rgba="1 0 0 1"/>
                                </material>

                                <material name="trans_black">
                                        <color rgba="0.8 0.8 0.8 1"/>
                                </material>

                                <material name="orange">
                                        <color rgba="1 0.369 0.047 1"/>
                                </material>

                                <material name="bravo_black">
                                        <color rgba="0.3 0.3 0.3 0.7"/>
                                </material>

                                <material name="bravo_jaws_black">
                                        <color rgba="0.3 0.3 0.3 1"/>
                                </material>   
            <!--ROV-->
<link name="world"/>     

            <link name="mobile_base">
                    <visual>
                            <geometry>
                                <mesh filename="package://uvm_description/meshes/cyberov/cyberov_decimated.stl" scale="0.001 0.001 0.001"/>
                            </geometry>
                            <origin rpy="0 0 0" xyz="0.3 0 0.115"/>
                             <material name="trans_black"/>
                    </visual>
            </link>
            
            <link name="toolskidR">
                    <visual>
                            <geometry>
                                <box size="0.8 0.025 0.3"/>
                            </geometry>
                            <material name="trans_black"/>
                    </visual>
            </link>
                    <joint name="falcon2toolskidR" type="fixed">
                        <parent link="mobile_base"/>
                        <child link="toolskidR"/>
                        <origin rpy="0 0 0" xyz="0.0 0.24 -0.15"/>
                    </joint>

            <link name="toolskidL">
                    <visual>
                            <geometry>
                                <box size="0.8 0.025 0.3"/>
                            </geometry>
                            <material name="trans_black"/>
                    </visual>
            </link>
                    <joint name="falcon2toolskidL" type="fixed">
                        <parent link="mobile_base"/>
                        <child link="toolskidL"/>
                        <origin rpy="0 0 0" xyz="0.0 -0.24 -0.15"/>
                    </joint>
            
            

            <link name="x_link"/>
            <link name="y_link"/>
            <link name="z_link"/>

                    <joint name="X" type="prismatic">
                        <parent link="world"/>
                        <child link="x_link"/>
                        <limit effort="1000.0" lower="-40.0" upper="40.0" velocity="10"/>
                        <origin rpy="0 0 0" xyz="0 0 0"/>
                        <axis xyz="1 0 0"/>
                    </joint>

                    <joint name="Y" type="prismatic">
                        <parent link="x_link"/>
                        <child link="y_link"/>
                        <limit effort="1000.0" lower="-40.0" upper="40.0" velocity="10"/>
                        <origin rpy="0 0 0" xyz="0 0 0"/>
                        <axis xyz="0 1 0"/>
                    </joint>

                    <joint name="Z" type="prismatic">
                        <parent link="y_link"/>
                        <child link="z_link"/>
                        <limit effort="1000.0" lower="-40.0" upper="40.0" velocity="10"/>
                        <origin rpy="0 0 0" xyz="0 0 0"/>
                        <axis xyz="0 0 1"/>
                    </joint>
                    
                    <joint name="Yaw" type="revolute">
                        <parent link="z_link"/>
                        <child link="mobile_base"/>
                        <origin rpy="0 0.0 3.14159" xyz="0 0 0"/>
                        <axis xyz="0 0 1"/>
                        <limit effort="10.0" lower="-8.0" upper="8.0" velocity="5"/>
                    </joint>

            <!--BRAVO ARM-->                    

            <link name="link1">
                <visual>
                    <geometry>
                        <mesh filename="package://uvm_description/meshes/RS2-266.stl"/>
                    </geometry>
                    <material name="blue"/>
                </visual>
            </link>

                    <joint name="base_fixed" type="fixed">
                        <parent link="mobile_base"/>
                        <child link="link1"/>
                        <origin rpy="3.14159 0 3.14159" xyz="-0.24 0.0 0.0"/>
                    </joint>

            <link name="link2">
                <visual>
                    <geometry>
                        <mesh filename="package://uvm_description/meshes/RS2-217.stl"/>
                    </geometry>
                    <material name="green2"/>
                    </visual>
            </link>

                    <joint name="joint1" type="revolute">
                        <parent link="link1"/>
                        <child link="link2"/>
                        <origin rpy="0 0 0" xyz="0.0665 0 0.078"/>
                        <axis xyz="0 0 -1"/>
                        <limit effort="9.0" lower="0.0" upper="6.3" velocity="0.5"/>
                    </joint>

            <link name="link3">
                <visual>
                    <geometry>
                        <mesh filename="package://uvm_description/meshes/RS2-250-212-214.stl"/>
                    </geometry>
                    <material name="blue"/>
                </visual>
            </link>

                    <joint name="joint2" type="revolute">
                        <parent link="link2"/>
                        <child link="link3"/>
                        <origin rpy="0 0 0" xyz="-0.046 0 0.0674"/>
                        <axis xyz="0 1 0"/>
                        <limit effort="9.0" lower="0.0" upper="3.5" velocity="0.5"/>
                    </joint>

            <link name="link4">
                <visual>
                    <geometry>
                        <mesh filename="package://uvm_description/meshes/RS2-268.stl"/>
                    </geometry>
                    <material name="green2"/>
                </visual>
            </link>

                    <joint name="joint3" type="revolute">
                        <parent link="link3"/>
                        <child link="link4"/>
                        <origin rpy="0 0 0" xyz="-0.0052 0 -0.29055"/>
                        <axis xyz="0 1 0"/>
                        <limit effort="9.0" lower="0.0" upper="3.5" velocity="0.5"/>
                    </joint>

            <link name="link5">
                <visual>
                    <geometry>
                        <mesh filename="package://uvm_description/meshes/RS2-214.stl"/>
                    </geometry>
                    <material name="blue"/>
                </visual>
            </link>

                    <joint name="joint4" type="revolute">
                        <parent link="link4"/>
                        <child link="link5"/>
                        <origin rpy="0 0 0" xyz="0.0408 0 0.09695"/>
                        <axis xyz="0 0 -1"/>
                        <limit effort="9.0" lower="0.0" upper="6.3" velocity="0.5"/>
                    </joint>

            <link name="link6">
                <visual>
                    <geometry>
                        <mesh filename="package://uvm_description/meshes/RS2-161.stl"/>
                    </geometry>
                    <material name="green2"/>
                </visual>
            </link>

                    <joint name="joint5" type="revolute">
                        <parent link="link5"/>
                        <child link="link6"/>
                        <origin rpy="0 0 0" xyz="-0.0408 0 0.063"/>
                        <axis xyz="0 1 0"/>
                        <limit effort="9.0" lower="0.0" upper="3.5" velocity="0.5"/>
                    </joint>

            <link name="link7">
                <visual>
                    <geometry>
                        <mesh filename="package://uvm_description/meshes/RS2-180.stl"/>
                    </geometry>
                    <material name="blue"/>
                </visual>
            </link>

            <link name="end_effector_ball">
                <visual>
                    <geometry>
                        <mesh filename="package://uvm_description/meshes/EndEffector_85mm.STL" scale="0.001 0.001 0.001"/>
                    </geometry>
                    <material name="red"/>
                </visual>
            </link>

                    <joint name="joint6" type="revolute">
                        <parent link="link6"/>
                        <child link="link7"/>
                        <origin rpy="0 3.14159 0" xyz="-0.0408 0 -0.08863"/>
                        <axis xyz="0 0 -1"/>
                        <limit effort="9.0" lower="0.0" upper="6.3" velocity="0.5"/>
                    </joint>

                    <joint name="bravo_EE_joint" type="fixed">
                        <origin rpy="0 -1.57 0" xyz=" 0.045 -0.035 0.113"/>
                        <parent link="link7"/>
                        <child link="end_effector_ball"/>
                    </joint>     

                    <joint name="contact_point_joint" type="fixed">
                        <origin rpy="0 0 0" xyz="0 0 0.24"/>
                        <parent link="link7"/>
                        <child link="contact_point"/>
                    </joint>

            <!-- contact_point -->
            <link name="contact_point"/>

</robot>
