<?xml version="1.0"?>
<robot name="bluevolta_bravo" xmlns:xacro="http://ros.org/wiki/xacro">

        <xacro:macro name="bluevolta_bravo" params="parent *origin  name:=bluevolta_bravo">   
                                <material name="${name}_green2">
                                        <color rgba="0.235 0.702 0.443 1"/>
                                </material>

                                <material name="${name}_blue">
                                        <color rgba="0.263 0.733 0.984 1"/>
                                </material>

                                <material name="${name}_trans_black">
                                        <color rgba="0.8 0.8 0.8 1"/>
                                </material>

                                <material name="${name}_black2">
                                        <color rgba="0.8 0.8 0.8 1"/>
                                </material>

                                <material name="${name}_orange">
                                        <color rgba="1 0.369 0.047 1"/>
                                </material>

                                <material name="${name}_green">
                                        <color rgba="0 1 0 0.5"/>
                                </material>

                                <material name="${name}_bravo_black">
                                        <color rgba="0.3 0.3 0.3 1"/>
                                </material>

                                <material name="${name}_bravo_jaws_black">
                                        <color rgba="0.3 0.3 0.3 1"/>
                                </material>   
            
            <link name="mobile_base">
                    <visual>
                            <geometry>
                                <mesh filename="package://uvm_description/meshes/bluevolta/bluevolta_base.obj" scale="1 1 1"/>
                            </geometry>
                            <material name="${name}_blue"/>
                    </visual>
            </link>
            
                    <joint name="link_rov1" type="fixed">
                        <origin xyz="0 0 0" rpy="0 0 0"/>
                        <parent link="mobile_base"/>
                        <child link="mobile_base2"/>
                    </joint>
            
           <link name="mobile_base2">
                    <visual>
                            <geometry>
                                <mesh filename="package://uvm_description/meshes/bluevolta/bluevolta.obj" scale="1 1 1"/>
                            </geometry>
                            <material name="${name}_bravo_black"/>
                    </visual>
            </link>
            
            <link name="box_base_bravo">
                <visual>
                    <geometry>
                        <box size="0.1 0.1 0.1"/>
                    </geometry>
                    <material name="${name}_orange"/>
                </visual>
            </link>


		<joint name="box_base_bravo_joint" type="fixed">
		        <origin xyz="-0.25 0.835 0.17" rpy="0 0 0"/>
			<parent link="mobile_base2"/>
			<child link="box_base_bravo"/>
		</joint>
		
	        
	        <joint name="BlueVoltaToRB7" type="fixed">
	        	<origin rpy="3.14 0.0 1.570796327" xyz="0 -0.05 -0.05"/>
			<parent link="box_base_bravo"/>
			<child link="bravo_base_link"/>
		</joint>
            
            


            <link name="bravo_base_link"/>


            <link name="x_link"/>
            <link name="y_link"/>
            <link name="z_link"/>
            

                    <joint name="X" type="prismatic">
                        <parent link="world"/>
                        <child link="x_link"/>
                        <limit effort="1000.0" lower="-40.0" upper="40.0" velocity="10"/>
                        <origin rpy="0 0 0" xyz="0 0 0"/>
                        <axis xyz="1 0 0"/>
                    </joint>

                    <joint name="Y" type="prismatic">
                        <parent link="x_link"/>
                        <child link="y_link"/>
                        <limit effort="1000.0" lower="-40.0" upper="40.0" velocity="10"/>
                        <origin rpy="0 0 0" xyz="0 0 0"/>
                        <axis xyz="0 1 0"/>
                    </joint>

                    <joint name="Z" type="prismatic">
                        <parent link="y_link"/>
                        <child link="z_link"/>
                        <limit effort="1000.0" lower="-40.0" upper="40.0" velocity="10"/>
                        <origin rpy="0 0 0" xyz="0 0 0"/>
                        <axis xyz="0 0 1"/>
                    </joint>
                    
                    <joint name="Yaw" type="revolute">
                        <parent link="z_link"/>
                        <child link="mobile_base"/>
                        <origin rpy="0 3.141592654 -1.570796327" xyz="0 0 0"/>
                        <axis xyz="0 0 1"/>
                        <limit effort="10.0" lower="-1000.0" upper="1000" velocity="5"/>
                    </joint>



            <link name="link1">
                <visual>
                    <geometry>
                        <mesh filename="package://uvm_description/meshes/RS2-266.stl"/>
                    </geometry>
                    <material name="${name}_blue"/>
                </visual>
            </link>

                    <joint name="base_fixed" type="fixed">
                        <parent link="bravo_base_link"/>
                        <child link="link1"/>
                        <origin rpy="0 0 0"/>
                    </joint>

            <link name="link2">
                <visual>
                    <geometry>
                        <mesh filename="package://uvm_description/meshes/RS2-217.stl"/>
                    </geometry>
                    <material name="${name}_green2"/>
                    </visual>
            </link>

                    <joint name="joint1" type="revolute">
                        <parent link="link1"/>
                        <child link="link2"/>
                        <origin rpy="0 0 0" xyz="0.0665 0 0.078"/>
                        <axis xyz="0 0 -1"/>
                        <limit effort="9.0" lower="-6.3" upper="6.3" velocity="0.5"/>
                    </joint>

            <link name="link3">
                <visual>
                    <geometry>
                        <mesh filename="package://uvm_description/meshes/RS2-250-212-214.stl"/>
                    </geometry>
                    <material name="${name}_blue"/>
                </visual>
            </link>

                    <joint name="joint2" type="revolute">
                        <parent link="link2"/>
                        <child link="link3"/>
                        <origin rpy="0 0 0" xyz="-0.046 0 0.0674"/>
                        <axis xyz="0 1 0"/>
                        <limit effort="9.0" lower="-3.5" upper="3.5" velocity="0.5"/>
                    </joint>

            <link name="link4">
                <visual>
                    <geometry>
                        <mesh filename="package://uvm_description/meshes/RS2-268.stl"/>
                    </geometry>
                    <material name="${name}_green2"/>
                </visual>
            </link>

                    <joint name="joint3" type="revolute">
                        <parent link="link3"/>
                        <child link="link4"/>
                        <origin rpy="0 0 0" xyz="-0.0052 0 -0.29055"/>
                        <axis xyz="0 1 0"/>
                        <limit effort="9.0" lower="-3.5" upper="3.5" velocity="0.5"/>
                    </joint>

            <link name="link5">
                <visual>
                    <geometry>
                        <mesh filename="package://uvm_description/meshes/RS2-214.stl"/>
                    </geometry>
                    <material name="${name}_blue"/>
                </visual>
            </link>

                    <joint name="joint4" type="revolute">
                        <parent link="link4"/>
                        <child link="link5"/>
                        <origin rpy="0 0 0" xyz="0.0408 0 0.09695"/>
                        <axis xyz="0 0 -1"/>
                        <limit effort="9.0" lower="-6.3" upper="6.3" velocity="0.5"/>
                    </joint>

            <link name="link6">
                <visual>
                    <geometry>
                        <mesh filename="package://uvm_description/meshes/RS2-161.stl"/>
                    </geometry>
                    <material name="${name}_green2"/>
                </visual>
            </link>

                    <joint name="joint5" type="revolute">
                        <parent link="link5"/>
                        <child link="link6"/>
                        <origin rpy="0 0 0" xyz="-0.0408 0 0.063"/>
                        <axis xyz="0 1 0"/>
                        <limit effort="9.0" lower="-3.5" upper="3.5" velocity="0.5"/>
                    </joint>

            <link name="link7">
                <visual>
                    <geometry>
                        <mesh filename="package://uvm_description/meshes/RS2-180.stl"/>
                    </geometry>
                    <material name="${name}_blue"/>
                </visual>
            </link>

            <link name="force_torque_sensor">
                <visual>
                    <geometry>
                        <cylinder length="0.06" radius="0.04"/>
                    </geometry>
                    <material name="${name}_orange"/>
                </visual>
            </link>

                    <joint name="FT_fixed_1" type="fixed">
                        <origin rpy="0 0 1.57" xyz=" 0 0 -0.03"/>
                        <parent link="link7"/>
                        <child link="force_torque_sensor"/>
                    </joint>

                    <joint name="joint6" type="revolute">
                        <parent link="link6"/>
                        <child link="link7"/>
                        <origin rpy="0 3.14159 0" xyz="-0.0408 0 -0.14863"/>
                        <axis xyz="0 0 -1"/>
                        <limit effort="9.0" lower="0.0" upper="6.3" velocity="0.5"/>
                    </joint>

                    <joint name="bravo_jaws_joint" type="fixed">
                        <origin rpy="0 0 0" xyz=" 0 0 0.124"/>
                        <parent link="link7"/>
                        <child link="bravo_jaws_base_link"/>
                    </joint>

            <link name="bravo_jaws_base_link"/>           

                    <!-- contact_point_joint -->
                    <joint name="contact_point_joint" type="fixed">
                        <!-- 0.16/0.185 for plastic/metal tool with boardmarker-->
                        <!-- 0.15/0.21 for blue/white polymer tool with sponge -->
                        <origin rpy="0 0 0" xyz="0 0 0.315"/>
                        <parent link="force_torque_sensor"/>
                        <child link="contact_point"/>
                    </joint>

            <!-- contact_point -->
            <link name="contact_point">
                <visual>
                <origin rpy="0 0 0" xyz="0 0 0"/>
                <geometry>
                    <sphere radius="0.01"/>
                </geometry>
                <material name="${name}_blue"/>
                </visual>
            </link>

            <link name="end_effector">
                <visual>
                <origin rpy="0 0 0" xyz="0 0 0"/>
                <geometry>
                    <cylinder radius="0.01" length="0.165"/>
                </geometry>
                <material name="${name}_blue"/>
                </visual>
            </link>


                    <joint name="tool" type="fixed">
                        <parent link="contact_point"/>
                        <child link="end_effector"/>
                        <origin rpy="0 0 0" xyz="0 0 -0.083"/>
                    </joint>

        </xacro:macro>
</robot>



