<?xml version="1.0" encoding="utf-8"?>
<robot name="bravo_5">

<material name="green2">
  <color rgba="0.235 0.702 0.443 1"/>
</material>

<material name="blue">
  <color rgba="0.263 0.733 0.984 1"/>
</material>

<material name="trans_black">
  <color rgba="0.8 0.8 0.8 1"/>
</material>

<material name="black2">
  <color rgba="0.8 0.8 0.8 1"/>
</material>

<material name="orange">
  <color rgba="1 0.369 0.047 1"/>
</material>

<material name="green">
  <color rgba="0 1 0 0.5"/>
</material>

<material name="bravo_black">
  <color rgba="0.3 0.3 0.3 0.7"/>
</material>

<material name="bravo_jaws_black">
    <color rgba="0.3 0.3 0.3 1"/>
</material>

<link name="base_link"/>

    <joint name="bravo_joint" type="fixed">
        <origin rpy="0 0 0" xyz="0 0 0"/>
        <parent link="base_link"/>
        <child link="bravo_base_link"/>
        <origin rpy="0 0 0" xyz="0 0 0"/>
    </joint>
  
<link name="bravo_base_link">
    <visual>
    <geometry>
        <mesh filename="package://uvm_description/meshes/RS2-1019_base.stl"/>
    </geometry>
    <material name="blue"/>
    </visual>
</link>

        <joint name="joint1" type="revolute">
            <parent link="bravo_base_link"/>
            <origin rpy="0 0 3.14159" xyz="0.0665 0 0.08"/>
            <axis xyz="0 0 -1"/>
            <child link="link1_1"/>
            <limit effort="0" lower="0.0" upper="6.3" velocity="0"/>
        </joint>

<link name="link1_1">
    <visual>
        <geometry>
        <mesh filename="package://uvm_description/meshes/RS2-1019_end.stl"/>
        </geometry>
        <material name="green2"/>
    </visual>
</link>

        <joint name="bravo_d_base_joint" type="fixed">
            <parent link="link1_1"/>
            <origin rpy="0 0 0" xyz="0 0 0"/>
            <child link="link1_2"/>
        </joint>

<link name="link1_2">
    <visual>
        <geometry>
        <mesh filename="package://uvm_description/meshes/RS2-1013_base.stl"/>
        </geometry>
        <material name="blue"/>
    </visual>
</link>

        <joint name="joint2" type="revolute">
            <parent link="link1_2"/>
            <origin rpy="0 0 0" xyz="0.046 0 0.0642"/>
            <axis xyz="0 -1 0"/>
            <child link="link2_1"/>
            <limit effort="0" lower="0.0" upper="3.2" velocity="0"/>
        </joint>

<link name="link2_1">
    <visual>
        <geometry>
        <mesh filename="package://uvm_description/meshes/RS2-1013_end.stl"/>
        </geometry>
        <material name="green2"/>
    </visual>
</link>

        <joint name="fixed0" type="fixed">
            <parent link="link2_1"/>
            <origin rpy="3.14159 0 3.14159" xyz="0.046 0 -0.05055"/>
            <child link="bravo_1013_end_link"/>
        </joint>

<link name="bravo_1013_end_link"/>

        <joint name="fixed1" type="fixed">
            <parent link="bravo_1013_end_link"/>
            <origin rpy="0 0 0" xyz="0 0 0.182"/>
            <child link="link2_3"/>
        </joint>

<link name="link2_2">
    <visual>
    <geometry>
        <mesh filename="package://uvm_description/meshes/RS2-1030.stl"/>
    </geometry>
    <material name="blue"/>
    </visual>
</link>

        <joint name="fixed4" type="fixed">
            <parent link="bravo_1013_end_link"/>
            <child link="link2_2"/>
            <origin rpy="0 0 0" xyz="0 0 0"/>
        </joint>

<link name="link2_3">
    <visual>
        <geometry>
        <mesh filename="package://uvm_description/meshes/RS2-1023_0_base.stl"/>
        </geometry>
        <material name="blue"/>
    </visual>
</link>

        <joint name="joint3" type="revolute">
            <parent link="link2_3"/>
            <origin rpy="0 0 0" xyz="0.042 0 0.0578"/>
            <axis xyz="0 -1 0"/>
            <child link="link3"/>
            <limit effort="0" lower="0.0" upper="3.2" velocity="0"/>
        </joint>

<link name="link3">
    <visual>
        <geometry>
        <mesh filename="package://uvm_description/meshes/RS2-1023_0_end.stl"/>
        </geometry>
        <material name="green2"/>
    </visual>
</link>

        <joint name="fixed2" type="fixed">
            <parent link="link3"/>
            <origin rpy="3.14159 0 0" xyz="0.0408 0 -0.09385"/>
            <child link="bravo_1023_0_end_link"/>
        </joint>

  <link name="bravo_1023_0_end_link"/>

        <joint name="fixed3" type="fixed">
            <parent link="bravo_1023_0_end_link"/>
            <origin rpy="0 0 0" xyz="0 0 0"/>
            <child link="link4_0"/>
        </joint>

  <link name="link4_0"/>

        <joint name="joint4" type="revolute">
            <parent link="link4_0"/>
            <origin rpy="0 0 0" xyz="0 0 0.0005"/>
            <axis xyz="0 0 -1"/>
            <child link="link4_1"/>
            <limit effort="0" lower="-1000" upper="1000" velocity="0"/>
        </joint>

<link name="link4_1">
    <visual>
        <geometry>
        <mesh filename="package://uvm_description/meshes/RS2-1023_1_end.stl"/>
        </geometry>
        <material name="blue"/>
    </visual>
</link>

        <joint name="bravo_1023_1_end_joint" type="fixed">
            <parent link="link4_1"/>
            <origin rpy="0 0 0" xyz="0 0 0.0056"/>
            <child link="bravo_1023_1_end_link"/>
        </joint>

<link name="bravo_1023_1_end_link"/>

        <joint name="bravo_a_base_joint" type="fixed">
            <parent link="bravo_1023_1_end_link"/>
            <origin rpy="0 0 0" xyz="0 0 0"/>
            <child link="link4_2"/>
        </joint>

<link name="link4_2">
    <visual>
        <geometry>
        <mesh filename="package://uvm_description/meshes/RS2-1028.stl"/>
        </geometry>
        <material name="blue"/>
    </visual>
</link>

        <joint name="fixed_ee" type="fixed">
            <parent link="link4_2"/>
            <origin rpy="0.0 0 0" xyz="0 0 0.120"/>
            <child link="end_effector"/>
        </joint>

<link name="end_effector"/>

        <joint name="fixed_contact_point" type="fixed">
            <parent link="end_effector"/>
            <origin rpy="0 0 0" xyz="0 0 0.05"/>
            <child link="contact_point"/>
        </joint>

<link name="contact_point"/>

</robot>

