<?xml version="1.0"?>
<robot name="bravo_7_ft" xmlns:xacro="http://ros.org/wiki/xacro">
     <xacro:macro name="bravo_7_ft" params="parent *origin  name:=bravo_7_ft">  
               
                <material name="bravo_black">
                    <color rgba="0.3 0.3 0.3 1"/>
                </material>
                
                <material name="bravo_jaws_black">
                    <color rgba="0.3 0.3 0.3 1"/>
                </material>
        

        <link name="base_link"/>

                <joint name="world_base" type="fixed">
                    <origin xyz="0 0 0" rpy="0 0 0"/>
                    <parent link="world"/>
                    <child link="base_link"/>
                </joint>


        <link name="bravo_base_link"/>

                <joint name="bravo_joint" type="fixed">
                    <origin rpy="0 0 0" xyz="0 0 0"/>
                    <parent link="base_link"/>
                    <child link="bravo_base_link"/>
                </joint>


        <link name="link1">
            <visual>
                <geometry>
                    <mesh filename="package://uvm_description/meshes/RS2-266.stl"/>
                </geometry>
                <material name="bravo_black"/>
            </visual>
        </link>

                <joint name="base_fixed" type="fixed">
                    <parent link="bravo_base_link"/>
                    <child link="link1"/>
                    <origin rpy="0 0 0"/>
                </joint>

        <link name="link2">
            <visual>
                <geometry>
                    <mesh filename="package://uvm_description/meshes/RS2-217.stl"/>
                </geometry>
                <material name="bravo_black"/>
            </visual>
        </link>

                <joint name="joint1" type="revolute">
                    <parent link="link1"/>
                    <child link="link2"/>
                    <origin rpy="0 0 0" xyz="0.0665 0 0.078"/>
                    <axis xyz="0 0 -1"/>
                    <limit effort="9.0" lower="0.0" upper="6.3" velocity="0.5"/>
                </joint>

        <link name="link3">
            <visual>
                <geometry>
                    <mesh filename="package://uvm_description/meshes/RS2-250-212-214.stl"/>
                </geometry>
                <material name="bravo_black"/>
            </visual>
        </link>

                <joint name="joint2" type="revolute">
                    <parent link="link2"/>
                    <child link="link3"/>
                    <origin rpy="0 0 0" xyz="-0.046 0 0.0674"/>
                    <axis xyz="0 1 0"/>
                    <limit effort="9.0" lower="0.0" upper="3.5" velocity="0.5"/>
                </joint>

        <link name="link4">
            <visual>
                <geometry>
                    <mesh filename="package://uvm_description/meshes/RS2-268.stl"/>
                </geometry>
                <material name="bravo_black"/>
            </visual>
        </link>

                <joint name="joint3" type="revolute">
                    <parent link="link3"/>
                    <child link="link4"/>
                    <origin rpy="0 0 0" xyz="-0.0052 0 -0.29055"/>
                    <axis xyz="0 1 0"/>
                    <limit effort="9.0" lower="0.0" upper="3.5" velocity="0.5"/>
                </joint>

        <link name="link5">
            <visual>
                <geometry>
                    <mesh filename="package://uvm_description/meshes/RS2-214.stl"/>
                </geometry>
                <material name="bravo_black"/>
            </visual>
        </link>

                <joint name="joint4" type="revolute">
                    <parent link="link4"/>
                    <child link="link5"/>
                    <origin rpy="0 0 0" xyz="0.0408 0 0.09695"/>
                    <axis xyz="0 0 -1"/>
                    <limit effort="9.0" lower="0.0" upper="6.3" velocity="0.5"/>
                </joint>

        <link name="link6">
            <visual>
                <geometry>
                    <mesh filename="package://uvm_description/meshes/RS2-161.stl"/>
                </geometry>
                <material name="bravo_black"/>
            </visual>
        </link>

                <joint name="joint5" type="revolute">
                    <parent link="link5"/>
                    <child link="link6"/>
                    <origin rpy="0 0 0" xyz="-0.0408 0 0.063"/>
                    <axis xyz="0 1 0"/>
                    <limit effort="9.0" lower="0.0" upper="3.5" velocity="0.5"/>
                </joint>

        <link name="link7">
            <visual>
                <geometry>
                    <mesh filename="package://uvm_description/meshes/RS2-180.stl"/>
                </geometry>
                <material name="bravo_black"/>
            </visual>
        </link>

        <link name="force_torque_sensor">
            <visual>
                <geometry>
                    <cylinder length="0.06" radius="0.04"/>
                </geometry>
                <material name="${name}_orange"/>
            </visual>
        </link>

                <joint name="FT_fixed_1" type="fixed">
                    <origin rpy="0 0 1.57" xyz=" 0 0 -0.03"/>
                    <parent link="link7"/>
                    <child link="force_torque_sensor"/>
                </joint>

                <joint name="joint6" type="revolute">
                    <parent link="link6"/>
                    <child link="link7"/>
                    <origin rpy="0 3.14159 0" xyz="-0.0408 0 -0.14863"/>
                    <axis xyz="0 0 -1"/>
                    <limit effort="9.0" lower="0.0" upper="6.3" velocity="0.5"/>
                </joint>

                <joint name="bravo_jaws_joint" type="fixed">
                    <origin rpy="0 0 0" xyz=" 0 0 0.124"/>
                    <parent link="link7"/>
                    <child link="bravo_jaws_base_link"/>
                </joint>

        <link name="bravo_jaws_base_link">
            <visual>
                <geometry>
                    <mesh filename="package://uvm_description/meshes/end_effectors/RS2-257.stl"/>
                </geometry>
                <material name="bravo_jaws_black"/>
            </visual>
        </link>

        <link name="bravo_push_rod"/>

                <joint name="gripper" type="prismatic">
                    <origin rpy="0 0 0" xyz="0 0 0.009"/>
                    <parent link="bravo_jaws_base_link"/>
                    <child link="bravo_push_rod"/>
                    <axis xyz="0 0 1"/>
                    <limit effort="10" lower="0" upper="0.035" velocity="10"/>
                </joint>

        <link name="bravo_rs2_255_link">
            <visual>
                <geometry>
                    <mesh filename="package://uvm_description/meshes/end_effectors/RS2-255.stl"/>
                </geometry>
            <material name="bravo_jaws_black"/>
            <origin rpy="0 0 0" xyz="0 0 0"/>
            </visual>
        </link>

                <joint name="bravo_rs2_255_joint" type="revolute">
                    <origin rpy="0 0 0" xyz="0 0.033 0.0097"/>
                    <parent link="bravo_jaws_base_link"/>
                    <child link="bravo_rs2_255_link"/>
                    <axis xyz="-1 0 0"/>
                    <limit effort="10" lower="0" upper="0.5" velocity="10"/>
                    <mimic joint="gripper" multiplier="15" offset="0"/>
                </joint>

        <link name="bravo_rs2_255_jaw_inside_link">
            <visual>
                <geometry>
                    <mesh filename="package://uvm_description/meshes/end_effectors/RS2-255-Jaw-Inside.stl"/>
                </geometry>
                <material name="bravo_jaws_black"/>
                <origin rpy="0 0 0" xyz="0 0 0"/>
            </visual>
        </link>

                <joint name="bravo_rs2_255_jaw_inside_joint" type="revolute">
                    <origin rpy="0 0 0" xyz="0 -0.033 0.0097"/>
                    <parent link="bravo_jaws_base_link"/>
                    <child link="bravo_rs2_255_jaw_inside_link"/>
                    <axis xyz="1 0 0"/>
                    <limit effort="10" lower="0" upper="0.5" velocity="10"/>
                    <mimic joint="gripper" multiplier="15" offset="0"/>
                </joint>

        <!-- add end_effector frame -->
        <link name="tip"/>

                <joint name="arm_to_tip" type="fixed">
                    <parent link="bravo_jaws_base_link"/>
                    <child link="tip"/>
                    <origin xyz="0 0 0.10" rpy="0 0 0"/>
                </joint>

        </xacro:macro>
</robot>

    
  

