<?xml version="1.0" encoding="utf-8"?>
<robot name="bravo7_sphere_endeffector">
  <!-- ===== Materials ===== -->
  <material name="green2">
    <color rgba="0.235 0.702 0.443 1"/>
  </material>

  <material name="blue">
    <color rgba="0.263 0.733 0.984 1"/>
  </material>

  <material name="trans_black">
    <color rgba="0.8 0.8 0.8 1"/>
  </material>

  <material name="black2">
    <color rgba="0.8 0.8 0.8 1"/>
  </material>

  <material name="orange">
    <color rgba="1 0.369 0.047 1"/>
  </material>

  <material name="green">
    <color rgba="0 1 0 0.5"/>
  </material>

  <material name="bravo_black">
    <color rgba="0.3 0.3 0.3 0.7"/>
  </material>

  <material name="bravo_jaws_black">
    <color rgba="0.3 0.3 0.3 1"/>
  </material>

  <material name="red">
          <color rgba="1 0 0 1"/>
  </material>

  <!-- ===== Links & Joints ===== -->
  <link name="bravo_base_link"/>

  <link name="link1">
    <!-- Inertial corrected into geometry frame -->
    <inertial>
      <origin xyz="0.0525 -0.001 0.04345" rpy="0 0 0"/>
      <mass value="1.85"/>
      <inertia ixx="0.002528" ixy="-2.0e-05" ixz="2.3e-05"
               iyy="0.002593" iyz="-7.0e-06" izz="0.003312"/>
    </inertial>
    <visual>
      <geometry>
        <mesh filename="package://bravo_arm_description/meshes_2/RS2-266.stl"/>
      </geometry>
      <material name="blue"/>
    </visual>
    <collision>
        <geometry>
            <mesh filename="package://bravo_arm_description/meshes_2/RS2-266_convex_hull.stl"/>
        </geometry>
    </collision>
  </link>

  <joint name="base_fixed" type="fixed">
    <parent link="bravo_base_link"/>
    <child link="link1"/>
    <origin rpy="0 0 0"/>
  </joint>

  <link name="link2">
    <inertial>
      <origin xyz="-0.03 0.01 0.06145" rpy="0 0 0"/>
      <mass value="1.62"/>
      <inertia ixx="0.003179" ixy="0.000233" ixz="0.001024"
               iyy="0.004209" iyz="-0.000344" izz="0.002387"/>
    </inertial>
    <visual>
      <geometry>
        <mesh filename="package://bravo_arm_description/meshes_2/RS2-217.stl"/>
      </geometry>
      <material name="green2"/>
    </visual>
    <collision>
        <geometry>
            <mesh filename="package://bravo_arm_description/meshes_2/RS2-217_convex_hull.stl"/>
        </geometry>
    </collision>
  </link>

  <joint name="joint1" type="revolute">
    <parent link="link1"/>
    <child link="link2"/>
    <origin rpy="0 0 0" xyz="0.0665 0 0.078"/>
    <axis xyz="0 0 -1"/>
    <limit effort="9.0" lower="0.0" upper="6.3" velocity="0.5"/>
  </joint>

  <link name="link3">
    <inertial>
      <origin xyz="-0.0241436 0.00399889 -0.1620485" rpy="0 0 0"/>
      <mass value="2.12"/>
      <inertia ixx="0.0352226436" ixy="-2.26528218e-05" ixz="0.00129923425"
               iyy="0.0359810399" iyz="0.00315070263" izz="0.00336331658"/>
    </inertial>
    <visual>
      <geometry>
        <mesh filename="package://bravo_arm_description/meshes_2/RS2-250-212-214.stl"/>
      </geometry>
      <material name="blue"/>
    </visual>
    <collision>
        <geometry>
            <mesh filename="package://bravo_arm_description/meshes_2/RS2-250-212-214_convex_hull.stl"/>
        </geometry>
    </collision>
  </link>

  <joint name="joint2" type="revolute">
    <parent link="link2"/>
    <child link="link3"/>
    <origin rpy="0 0 0" xyz="-0.046 0 0.0674"/>
    <axis xyz="0 1 0"/>
    <limit effort="9.0" lower="0.0" upper="3.5" velocity="0.5"/>
  </joint>

  <link name="link4">
    <inertial>
      <origin xyz="0.03499989 -0.00300155 0.05931046" rpy="0 0 0"/>
      <mass value="1.33"/>
      <inertia ixx="0.001809" ixy="-0.000156" ixz="-0.000398"
               iyy="0.002024" iyz="-0.000197" izz="0.001557"/>
    </inertial>
    <visual>
      <geometry>
        <mesh filename="package://bravo_arm_description/meshes_2/RS2-268.stl"/>
      </geometry>
      <material name="green2"/>
    </visual>
    <collision>
        <geometry>
            <mesh filename="package://bravo_arm_description/meshes_2/RS2-268_convex_hull.stl"/>
        </geometry>
        <material name="green"/>
    </collision>
  </link>

  <joint name="joint3" type="revolute">
    <parent link="link3"/>
    <child link="link4"/>
    <origin rpy="0 0 0" xyz="-0.0052 0 -0.29055"/>
    <axis xyz="0 1 0"/>
    <limit effort="9.0" lower="0.0" upper="3.5" velocity="0.5"/>
  </joint>

  <link name="link5">
    <inertial>
      <origin xyz="-0.02699995 0.01199816 0.06136048" rpy="0 0 0"/>
      <mass value="1.33"/>
      <inertia ixx="0.001983" ixy="0.00018" ixz="0.000641"
               iyy="0.002676" iyz="-0.000264" izz="0.001526"/>
    </inertial>
    <visual>
      <geometry>
        <mesh filename="package://bravo_arm_description/meshes_2/RS2-214.stl"/>
      </geometry>
      <material name="blue"/>
    </visual>
    <collision>
        <geometry>
            <mesh filename="package://bravo_arm_description/meshes_2/RS2-214_convex_hull.stl"/>
        </geometry>
    </collision>
  </link>

  <joint name="joint4" type="revolute">
    <parent link="link4"/>
    <child link="link5"/>
    <origin rpy="0 0 0" xyz="0.0408 0 0.09695"/>
    <axis xyz="0 0 -1"/>
    <limit effort="9.0" lower="0.0" upper="6.3" velocity="0.5"/>
  </joint>

  <link name="link6">
    <inertial>
      <origin xyz="-0.02999999 -0.00600209 -0.02537941" rpy="0 0 0"/>
      <mass value="0.97"/>
      <inertia ixx="0.001272" ixy="0.000116" ixz="-0.000346"
               iyy="0.001511" iyz="0.000189" izz="0.001205"/>
    </inertial>
    <visual>
      <geometry>
        <mesh filename="package://bravo_arm_description/meshes_2/RS2-161.stl"/>
      </geometry>
      <material name="green2"/>
    </visual>
    <collision>
        <geometry>
            <mesh filename="package://bravo_arm_description/meshes_2/RS2-161_convex_hull.stl"/>
        </geometry>
    </collision>
  </link>

  <joint name="joint5" type="revolute">
    <parent link="link5"/>
    <child link="link6"/>
    <origin rpy="0 0 0" xyz="-0.0408 0 0.063"/>
    <axis xyz="0 1 0"/>
    <limit effort="9.0" lower="0.0" upper="3.5" velocity="0.5"/>
  </joint>

  <link name="link7">
    <inertial>
      <origin xyz="-0.000999865 -0.00000344664 0.0247494355" rpy="0 0 0"/>
      <mass value="1.09"/>
      <inertia ixx="0.00197699995" ixy="1.88170062e-10" ixz="-1.50015577e-05"
               iyy="0.00198600003" iyz="-9.87966436e-07" izz="0.00103500002"/>
    </inertial>
    <visual>
      <geometry>
        <mesh filename="package://bravo_arm_description/meshes_2/RS2-180.stl"/>
      </geometry>
      <material name="blue"/>
    </visual>
    <collision>
        <geometry>
            <mesh filename="package://bravo_arm_description/meshes_2/RS2-180_convex_hull.stl"/>
        </geometry>
    </collision>
  </link>

  <joint name="joint6" type="revolute">
    <parent link="link6"/>
    <child link="link7"/>
    <origin rpy="0 3.14159 0" xyz="-0.0408 0 -0.08863"/>
    <axis xyz="0 0 -1"/>
    <limit effort="9.0" lower="0.0" upper="6.3" velocity="0.5"/>
  </joint>


  <link name="end_effector_ball">
    <visual>
        <geometry>
            <mesh filename="package://bravo_arm_description/meshes_2/end_effectors/contact_sphere.stl"/>
        </geometry>
        <material name="red"/>
    </visual>
    <collision>
        <geometry>
            <mesh filename="package://bravo_arm_description/meshes_2/end_effectors/contact_sphere_convex_hull.stl"/>
        </geometry>
        <material name="red"/>
    </collision>
</link>

      <joint name="bravo_EE_joint" type="fixed">
          <origin rpy="0 -1.57 0" xyz=" 0.045 -0.035 0.113"/>
          <parent link="link7"/>
          <child link="end_effector_ball"/>
      </joint>    

  <!-- contact_point -->
  <link name="contact_point"/> 

      <joint name="contact_point_joint" type="fixed">
          <origin rpy="0 0 0" xyz="0 0 0.21"/>
          <parent link="link7"/>
          <child link="contact_point"/>
      </joint>
</robot>
